[2023-09-29T09:27:49.566+0000] {taskinstance.py:1157} INFO - Dependencies all met for dep_context=non-requeueable deps ti=<TaskInstance: weather_dag.transform_load_weather_data manual__2023-09-29T09:27:39.932487+00:00 [queued]>
[2023-09-29T09:27:49.573+0000] {taskinstance.py:1157} INFO - Dependencies all met for dep_context=requeueable deps ti=<TaskInstance: weather_dag.transform_load_weather_data manual__2023-09-29T09:27:39.932487+00:00 [queued]>
[2023-09-29T09:27:49.573+0000] {taskinstance.py:1359} INFO - Starting attempt 1 of 1
[2023-09-29T09:27:49.587+0000] {taskinstance.py:1380} INFO - Executing <Task(PythonOperator): transform_load_weather_data> on 2023-09-29 09:27:39.932487+00:00
[2023-09-29T09:27:49.591+0000] {standard_task_runner.py:57} INFO - Started process 1376 to run task
[2023-09-29T09:27:49.596+0000] {standard_task_runner.py:84} INFO - Running: ['airflow', 'tasks', 'run', 'weather_dag', 'transform_load_weather_data', 'manual__2023-09-29T09:27:39.932487+00:00', '--job-id', '59', '--raw', '--subdir', 'DAGS_FOLDER/weather_dag.py', '--cfg-path', '/tmp/tmp26vmjjxc']
[2023-09-29T09:27:49.596+0000] {standard_task_runner.py:85} INFO - Job 59: Subtask transform_load_weather_data
[2023-09-29T09:27:49.637+0000] {task_command.py:415} INFO - Running <TaskInstance: weather_dag.transform_load_weather_data manual__2023-09-29T09:27:39.932487+00:00 [running]> on host ip-172-31-24-192.eu-north-1.compute.internal
[2023-09-29T09:27:49.694+0000] {taskinstance.py:1660} INFO - Exporting env vars: AIRFLOW_CTX_DAG_OWNER='airflow' AIRFLOW_CTX_DAG_ID='weather_dag' AIRFLOW_CTX_TASK_ID='transform_load_weather_data' AIRFLOW_CTX_EXECUTION_DATE='2023-09-29T09:27:39.932487+00:00' AIRFLOW_CTX_TRY_NUMBER='1' AIRFLOW_CTX_DAG_RUN_ID='manual__2023-09-29T09:27:39.932487+00:00'
[2023-09-29T09:27:49.696+0000] {taskinstance.py:1935} ERROR - Task failed with exception
Traceback (most recent call last):
  File "/home/ubuntu/airflow_venv/lib/python3.10/site-packages/airflow/operators/python.py", line 192, in execute
    return_value = self.execute_callable()
  File "/home/ubuntu/airflow_venv/lib/python3.10/site-packages/airflow/operators/python.py", line 209, in execute_callable
    return self.python_callable(*self.op_args, **self.op_kwargs)
  File "/home/ubuntu/airflow/dags/weather_dag.py", line 15, in transform_load_data
    data = task_instance.xcom_pull(task_id="extract_weather_data")
  File "/home/ubuntu/airflow_venv/lib/python3.10/site-packages/airflow/utils/session.py", line 77, in wrapper
    return func(*args, session=session, **kwargs)
TypeError: TaskInstance.xcom_pull() got an unexpected keyword argument 'task_id'
[2023-09-29T09:27:49.701+0000] {taskinstance.py:1398} INFO - Marking task as FAILED. dag_id=weather_dag, task_id=transform_load_weather_data, execution_date=20230929T092739, start_date=20230929T092749, end_date=20230929T092749
[2023-09-29T09:27:49.713+0000] {standard_task_runner.py:104} ERROR - Failed to execute job 59 for task transform_load_weather_data (TaskInstance.xcom_pull() got an unexpected keyword argument 'task_id'; 1376)
[2023-09-29T09:27:49.727+0000] {local_task_job_runner.py:228} INFO - Task exited with return code 1
[2023-09-29T09:27:49.743+0000] {taskinstance.py:2776} INFO - 0 downstream tasks scheduled from follow-on schedule check
