[2023-09-29T09:53:51.237+0000] {taskinstance.py:1157} INFO - Dependencies all met for dep_context=non-requeueable deps ti=<TaskInstance: weather_dag.transform_load_weather_data manual__2023-09-29T09:53:38.746957+00:00 [queued]>
[2023-09-29T09:53:51.243+0000] {taskinstance.py:1157} INFO - Dependencies all met for dep_context=requeueable deps ti=<TaskInstance: weather_dag.transform_load_weather_data manual__2023-09-29T09:53:38.746957+00:00 [queued]>
[2023-09-29T09:53:51.243+0000] {taskinstance.py:1359} INFO - Starting attempt 1 of 1
[2023-09-29T09:53:51.256+0000] {taskinstance.py:1380} INFO - Executing <Task(PythonOperator): transform_load_weather_data> on 2023-09-29 09:53:38.746957+00:00
[2023-09-29T09:53:51.261+0000] {standard_task_runner.py:57} INFO - Started process 3574 to run task
[2023-09-29T09:53:51.265+0000] {standard_task_runner.py:84} INFO - Running: ['airflow', 'tasks', 'run', 'weather_dag', 'transform_load_weather_data', 'manual__2023-09-29T09:53:38.746957+00:00', '--job-id', '69', '--raw', '--subdir', 'DAGS_FOLDER/weather_dag.py', '--cfg-path', '/tmp/tmplyx7zaws']
[2023-09-29T09:53:51.266+0000] {standard_task_runner.py:85} INFO - Job 69: Subtask transform_load_weather_data
[2023-09-29T09:53:51.301+0000] {task_command.py:415} INFO - Running <TaskInstance: weather_dag.transform_load_weather_data manual__2023-09-29T09:53:38.746957+00:00 [running]> on host ip-172-31-24-192.eu-north-1.compute.internal
[2023-09-29T09:53:51.354+0000] {taskinstance.py:1660} INFO - Exporting env vars: AIRFLOW_CTX_DAG_OWNER='airflow' AIRFLOW_CTX_DAG_ID='weather_dag' AIRFLOW_CTX_TASK_ID='transform_load_weather_data' AIRFLOW_CTX_EXECUTION_DATE='2023-09-29T09:53:38.746957+00:00' AIRFLOW_CTX_TRY_NUMBER='1' AIRFLOW_CTX_DAG_RUN_ID='manual__2023-09-29T09:53:38.746957+00:00'
[2023-09-29T09:53:51.360+0000] {taskinstance.py:1935} ERROR - Task failed with exception
Traceback (most recent call last):
  File "/home/ubuntu/airflow_venv/lib/python3.10/site-packages/airflow/operators/python.py", line 192, in execute
    return_value = self.execute_callable()
  File "/home/ubuntu/airflow_venv/lib/python3.10/site-packages/airflow/operators/python.py", line 209, in execute_callable
    return self.python_callable(*self.op_args, **self.op_kwargs)
  File "/home/ubuntu/airflow/dags/weather_dag.py", line 24, in transform_load_data
    wind_speed = data["main"]["speed"]
KeyError: 'speed'
[2023-09-29T09:53:51.364+0000] {taskinstance.py:1398} INFO - Marking task as FAILED. dag_id=weather_dag, task_id=transform_load_weather_data, execution_date=20230929T095338, start_date=20230929T095351, end_date=20230929T095351
[2023-09-29T09:53:51.377+0000] {standard_task_runner.py:104} ERROR - Failed to execute job 69 for task transform_load_weather_data ('speed'; 3574)
[2023-09-29T09:53:51.397+0000] {local_task_job_runner.py:228} INFO - Task exited with return code 1
[2023-09-29T09:53:51.410+0000] {taskinstance.py:2776} INFO - 0 downstream tasks scheduled from follow-on schedule check
