[2023-09-27T18:28:19.143+0000] {taskinstance.py:1157} INFO - Dependencies all met for dep_context=non-requeueable deps ti=<TaskInstance: weather_dag.API_readiness_check_call manual__2023-09-27T18:26:12.023116+00:00 [queued]>
[2023-09-27T18:28:19.151+0000] {taskinstance.py:1157} INFO - Dependencies all met for dep_context=requeueable deps ti=<TaskInstance: weather_dag.API_readiness_check_call manual__2023-09-27T18:26:12.023116+00:00 [queued]>
[2023-09-27T18:28:19.151+0000] {taskinstance.py:1359} INFO - Starting attempt 2 of 2
[2023-09-27T18:28:19.168+0000] {taskinstance.py:1380} INFO - Executing <Task(HttpSensor): API_readiness_check_call> on 2023-09-27 18:26:12.023116+00:00
[2023-09-27T18:28:19.171+0000] {standard_task_runner.py:57} INFO - Started process 14661 to run task
[2023-09-27T18:28:19.176+0000] {standard_task_runner.py:84} INFO - Running: ['airflow', 'tasks', 'run', 'weather_dag', 'API_readiness_check_call', 'manual__2023-09-27T18:26:12.023116+00:00', '--job-id', '14', '--raw', '--subdir', 'DAGS_FOLDER/weather_dag.py', '--cfg-path', '/tmp/tmp19yi9q6o']
[2023-09-27T18:28:19.176+0000] {standard_task_runner.py:85} INFO - Job 14: Subtask API_readiness_check_call
[2023-09-27T18:28:19.217+0000] {task_command.py:415} INFO - Running <TaskInstance: weather_dag.API_readiness_check_call manual__2023-09-27T18:26:12.023116+00:00 [running]> on host ip-172-31-24-192.eu-north-1.compute.internal
[2023-09-27T18:28:19.279+0000] {taskinstance.py:1660} INFO - Exporting env vars: AIRFLOW_CTX_DAG_OWNER='airflow' AIRFLOW_CTX_DAG_ID='weather_dag' AIRFLOW_CTX_TASK_ID='API_readiness_check_call' AIRFLOW_CTX_EXECUTION_DATE='2023-09-27T18:26:12.023116+00:00' AIRFLOW_CTX_TRY_NUMBER='2' AIRFLOW_CTX_DAG_RUN_ID='manual__2023-09-27T18:26:12.023116+00:00'
[2023-09-27T18:28:19.282+0000] {http.py:130} INFO - Poking: /data/3.0/onecall?lat={lat}&lon={lon}&appid={api_key}
[2023-09-27T18:28:19.291+0000] {base.py:73} INFO - Using connection ID 'weathermap_api' for task execution.
[2023-09-27T18:28:19.542+0000] {http.py:178} ERROR - HTTP error: Unauthorized
[2023-09-27T18:28:19.542+0000] {http.py:179} ERROR - {"cod":401, "message": "Please note that using One Call 3.0 requires a separate subscription to the One Call by Call plan. Learn more here https://openweathermap.org/price. If you have a valid subscription to the One Call by Call plan, but still receive this error, then please see https://openweathermap.org/faq#error401 for more info."}
[2023-09-27T18:28:19.550+0000] {taskinstance.py:1935} ERROR - Task failed with exception
Traceback (most recent call last):
  File "/home/ubuntu/airflow_venv/lib/python3.10/site-packages/airflow/providers/http/hooks/http.py", line 176, in check_response
    response.raise_for_status()
  File "/home/ubuntu/airflow_venv/lib/python3.10/site-packages/requests/models.py", line 1021, in raise_for_status
    raise HTTPError(http_error_msg, response=self)
requests.exceptions.HTTPError: 401 Client Error: Unauthorized for url: https://api.openweathermap.org/data/3.0/onecall?lat=%7Blat%7D&lon=%7Blon%7D&appid=%7Bapi_key%7D

During handling of the above exception, another exception occurred:

Traceback (most recent call last):
  File "/home/ubuntu/airflow_venv/lib/python3.10/site-packages/airflow/sensors/base.py", line 257, in execute
    raise e
  File "/home/ubuntu/airflow_venv/lib/python3.10/site-packages/airflow/sensors/base.py", line 239, in execute
    poke_return = self.poke(context)
  File "/home/ubuntu/airflow_venv/lib/python3.10/site-packages/airflow/providers/http/sensors/http.py", line 145, in poke
    raise exc
  File "/home/ubuntu/airflow_venv/lib/python3.10/site-packages/airflow/providers/http/sensors/http.py", line 132, in poke
    response = hook.run(
  File "/home/ubuntu/airflow_venv/lib/python3.10/site-packages/airflow/providers/http/hooks/http.py", line 166, in run
    return self.run_and_check(session, prepped_request, extra_options)
  File "/home/ubuntu/airflow_venv/lib/python3.10/site-packages/airflow/providers/http/hooks/http.py", line 217, in run_and_check
    self.check_response(response)
  File "/home/ubuntu/airflow_venv/lib/python3.10/site-packages/airflow/providers/http/hooks/http.py", line 180, in check_response
    raise AirflowException(str(response.status_code) + ":" + response.reason)
airflow.exceptions.AirflowException: 401:Unauthorized
[2023-09-27T18:28:19.555+0000] {taskinstance.py:1398} INFO - Marking task as FAILED. dag_id=weather_dag, task_id=API_readiness_check_call, execution_date=20230927T182612, start_date=20230927T182819, end_date=20230927T182819
[2023-09-27T18:28:19.570+0000] {standard_task_runner.py:104} ERROR - Failed to execute job 14 for task API_readiness_check_call (401:Unauthorized; 14661)
[2023-09-27T18:28:19.589+0000] {local_task_job_runner.py:228} INFO - Task exited with return code 1
[2023-09-27T18:28:19.607+0000] {taskinstance.py:2776} INFO - 0 downstream tasks scheduled from follow-on schedule check
