[2023-09-28T10:46:56.394+0000] {taskinstance.py:1157} INFO - Dependencies all met for dep_context=non-requeueable deps ti=<TaskInstance: weather_dag.extract_weather_data manual__2023-09-27T19:36:24.693710+00:00 [queued]>
[2023-09-28T10:46:56.404+0000] {taskinstance.py:1157} INFO - Dependencies all met for dep_context=requeueable deps ti=<TaskInstance: weather_dag.extract_weather_data manual__2023-09-27T19:36:24.693710+00:00 [queued]>
[2023-09-28T10:46:56.404+0000] {taskinstance.py:1359} INFO - Starting attempt 2 of 2
[2023-09-28T10:46:56.425+0000] {taskinstance.py:1380} INFO - Executing <Task(SimpleHttpOperator): extract_weather_data> on 2023-09-27 19:36:24.693710+00:00
[2023-09-28T10:46:56.430+0000] {standard_task_runner.py:57} INFO - Started process 1225 to run task
[2023-09-28T10:46:56.437+0000] {standard_task_runner.py:84} INFO - Running: ['airflow', 'tasks', 'run', 'weather_dag', 'extract_weather_data', 'manual__2023-09-27T19:36:24.693710+00:00', '--job-id', '29', '--raw', '--subdir', 'DAGS_FOLDER/weather_dag.py', '--cfg-path', '/tmp/tmpxp935pdb']
[2023-09-28T10:46:56.440+0000] {standard_task_runner.py:85} INFO - Job 29: Subtask extract_weather_data
[2023-09-28T10:46:56.484+0000] {task_command.py:415} INFO - Running <TaskInstance: weather_dag.extract_weather_data manual__2023-09-27T19:36:24.693710+00:00 [running]> on host ip-172-31-24-192.eu-north-1.compute.internal
[2023-09-28T10:46:56.560+0000] {taskinstance.py:1660} INFO - Exporting env vars: AIRFLOW_CTX_DAG_OWNER='airflow' AIRFLOW_CTX_DAG_ID='weather_dag' AIRFLOW_CTX_TASK_ID='extract_weather_data' AIRFLOW_CTX_EXECUTION_DATE='2023-09-27T19:36:24.693710+00:00' AIRFLOW_CTX_TRY_NUMBER='2' AIRFLOW_CTX_DAG_RUN_ID='manual__2023-09-27T19:36:24.693710+00:00'
[2023-09-28T10:46:56.562+0000] {http.py:143} INFO - Calling HTTP method
[2023-09-28T10:46:56.568+0000] {base.py:73} INFO - Using connection ID 'weathermap_api' for task execution.
[2023-09-28T10:46:56.833+0000] {http.py:178} ERROR - HTTP error: Unauthorized
[2023-09-28T10:46:56.834+0000] {http.py:179} ERROR - {"cod":401, "message": "Invalid API key. Please see https://openweathermap.org/faq#error401 for more info."}
[2023-09-28T10:46:56.839+0000] {taskinstance.py:1935} ERROR - Task failed with exception
Traceback (most recent call last):
  File "/home/ubuntu/airflow_venv/lib/python3.10/site-packages/airflow/providers/http/hooks/http.py", line 176, in check_response
    response.raise_for_status()
  File "/home/ubuntu/airflow_venv/lib/python3.10/site-packages/requests/models.py", line 1021, in raise_for_status
    raise HTTPError(http_error_msg, response=self)
requests.exceptions.HTTPError: 401 Client Error: Unauthorized for url: https://api.openweathermap.org/data/2.5/forecast?lat=%7Blat%7D&lon=%7Blon%7D&appid=%7Bapi_key%7D

During handling of the above exception, another exception occurred:

Traceback (most recent call last):
  File "/home/ubuntu/airflow_venv/lib/python3.10/site-packages/airflow/providers/http/operators/http.py", line 145, in execute
    response = http.run(self.endpoint, self.data, self.headers, self.extra_options)
  File "/home/ubuntu/airflow_venv/lib/python3.10/site-packages/airflow/providers/http/hooks/http.py", line 166, in run
    return self.run_and_check(session, prepped_request, extra_options)
  File "/home/ubuntu/airflow_venv/lib/python3.10/site-packages/airflow/providers/http/hooks/http.py", line 217, in run_and_check
    self.check_response(response)
  File "/home/ubuntu/airflow_venv/lib/python3.10/site-packages/airflow/providers/http/hooks/http.py", line 180, in check_response
    raise AirflowException(str(response.status_code) + ":" + response.reason)
airflow.exceptions.AirflowException: 401:Unauthorized
[2023-09-28T10:46:56.854+0000] {taskinstance.py:1398} INFO - Marking task as FAILED. dag_id=weather_dag, task_id=extract_weather_data, execution_date=20230927T193624, start_date=20230928T104656, end_date=20230928T104656
[2023-09-28T10:46:56.871+0000] {standard_task_runner.py:104} ERROR - Failed to execute job 29 for task extract_weather_data (401:Unauthorized; 1225)
[2023-09-28T10:46:56.888+0000] {local_task_job_runner.py:228} INFO - Task exited with return code 1
[2023-09-28T10:46:56.915+0000] {taskinstance.py:2776} INFO - 0 downstream tasks scheduled from follow-on schedule check
