[2023-09-29T09:32:34.427+0000] {taskinstance.py:1157} INFO - Dependencies all met for dep_context=non-requeueable deps ti=<TaskInstance: weather_dag.transform_load_weather_data manual__2023-09-29T09:32:22.530084+00:00 [queued]>
[2023-09-29T09:32:34.438+0000] {taskinstance.py:1157} INFO - Dependencies all met for dep_context=requeueable deps ti=<TaskInstance: weather_dag.transform_load_weather_data manual__2023-09-29T09:32:22.530084+00:00 [queued]>
[2023-09-29T09:32:34.439+0000] {taskinstance.py:1359} INFO - Starting attempt 1 of 1
[2023-09-29T09:32:34.460+0000] {taskinstance.py:1380} INFO - Executing <Task(PythonOperator): transform_load_weather_data> on 2023-09-29 09:32:22.530084+00:00
[2023-09-29T09:32:34.466+0000] {standard_task_runner.py:57} INFO - Started process 2292 to run task
[2023-09-29T09:32:34.473+0000] {standard_task_runner.py:84} INFO - Running: ['airflow', 'tasks', 'run', 'weather_dag', 'transform_load_weather_data', 'manual__2023-09-29T09:32:22.530084+00:00', '--job-id', '64', '--raw', '--subdir', 'DAGS_FOLDER/weather_dag.py', '--cfg-path', '/tmp/tmpno47dot0']
[2023-09-29T09:32:34.474+0000] {standard_task_runner.py:85} INFO - Job 64: Subtask transform_load_weather_data
[2023-09-29T09:32:34.516+0000] {task_command.py:415} INFO - Running <TaskInstance: weather_dag.transform_load_weather_data manual__2023-09-29T09:32:22.530084+00:00 [running]> on host ip-172-31-24-192.eu-north-1.compute.internal
[2023-09-29T09:32:34.579+0000] {taskinstance.py:1660} INFO - Exporting env vars: AIRFLOW_CTX_DAG_OWNER='airflow' AIRFLOW_CTX_DAG_ID='weather_dag' AIRFLOW_CTX_TASK_ID='transform_load_weather_data' AIRFLOW_CTX_EXECUTION_DATE='2023-09-29T09:32:22.530084+00:00' AIRFLOW_CTX_TRY_NUMBER='1' AIRFLOW_CTX_DAG_RUN_ID='manual__2023-09-29T09:32:22.530084+00:00'
[2023-09-29T09:32:34.588+0000] {taskinstance.py:1935} ERROR - Task failed with exception
Traceback (most recent call last):
  File "/home/ubuntu/airflow_venv/lib/python3.10/site-packages/airflow/operators/python.py", line 192, in execute
    return_value = self.execute_callable()
  File "/home/ubuntu/airflow_venv/lib/python3.10/site-packages/airflow/operators/python.py", line 209, in execute_callable
    return self.python_callable(*self.op_args, **self.op_kwargs)
  File "/home/ubuntu/airflow/dags/weather_dag.py", line 16, in transform_load_data
    city = data["name"]
KeyError: 'name'
[2023-09-29T09:32:34.595+0000] {taskinstance.py:1398} INFO - Marking task as FAILED. dag_id=weather_dag, task_id=transform_load_weather_data, execution_date=20230929T093222, start_date=20230929T093234, end_date=20230929T093234
[2023-09-29T09:32:34.617+0000] {standard_task_runner.py:104} ERROR - Failed to execute job 64 for task transform_load_weather_data ('name'; 2292)
[2023-09-29T09:32:34.644+0000] {local_task_job_runner.py:228} INFO - Task exited with return code 1
[2023-09-29T09:32:34.659+0000] {taskinstance.py:2776} INFO - 0 downstream tasks scheduled from follow-on schedule check
